coverage:
  all_nodes: 0
  covered_nodes: 0
mutation_score: 50.0
mutations:
- exception_traceback: "Traceback (most recent call last):\n  File \"C:\\Users\\skaspers\\\
    OneDrive - Capgemini\\Documents\\Prompted Testsuite Analysis\\.\\datasets\\pynguin\\\
    tests\\test_075.py\", line 14, in test_case_1\n    assert var_0 == 0\nAssertionError\n"
  killer: test_case_1 (datasets.pynguin.tests.test_075.TestAll)
  module: &id001 !!python/module:datasets.pynguin.programs.program_075 ''
  mutations:
  - lineno: 2
    operator: ROR
  number: 1
  status: killed
  tests_run: 2
  time: 0.0012373924255371094
- exception_traceback: null
  killer: null
  module: *id001
  mutations:
  - lineno: 2
    operator: ROR
  number: 2
  status: survived
  tests_run: 2
  time: 0.0
number_of_tests: 2
targets:
- datasets.pynguin.programs.program_075
tests:
- name: datasets.pynguin.tests.test_075
  target: null
  time: 0.0
time_stats:
  create_mutant_module: 0.001992940902709961
  create_target_ast: 0.0010061264038085938
  mutate_module: 0.024161100387573242
  run_tests_with_mutant: 0.0012373924255371094
total_time: 0.030172348022460938
