[*] Start mutation process:
   - targets: datasets.pynguin.programs.program_007
   - tests: datasets.pynguin.tests.test_007
[*] 1 tests passed:
   - datasets.pynguin.tests.test_007 [0.00000 s]
[*] Start mutants generation and execution:
   - [#   1] ROR datasets.pynguin.programs.program_007: [0.00100 s] killed by test_case_0 (datasets.pynguin.tests.test_007.TestAll)

Traceback (most recent call last):
  File "C:\Users\skaspers\OneDrive - Capgemini\Documents\Prompted Testsuite Analysis\.\datasets\pynguin\tests\test_007.py", line 10, in test_case_0
    assert var_0 is False
AssertionError

[*] Mutation score [0.02430 s]: 100.0%
   - all: 1
   - killed: 1 (100.0%)
   - survived: 0 (0.0%)
   - incompetent: 0 (0.0%)
   - timeout: 0 (0.0%)
HI SANDER, RUNNING MUTPY FROM: C:\Users\skaspers\OneDrive - Capgemini\Documents\Prompted Testsuite Analysis\.venv38\lib\site-packages\mutpy\commandline.py
