[*] Start mutation process:
   - targets: datasets.GPT_4.Zero_shot1.programs.program_069
   - tests: datasets.GPT_4.Zero_shot1.tests.test_069
[*] 8 tests passed:
   - datasets.GPT_4.Zero_shot1.tests.test_069 [0.00000 s]
[*] Start mutants generation and execution:
   - [#   1] AOD datasets.GPT_4.Zero_shot1.programs.program_069: [0.00000 s] killed by test_4 (datasets.GPT_4.Zero_shot1.tests.test_069.TestVersion)

Traceback (most recent call last):
  File "C:\Users\skaspers\OneDrive - Capgemini\Documents\Prompted Testsuite Analysis\.\datasets\GPT_4\Zero_shot1\tests\test_069.py", line 15, in test_4
    self.assertEqual(multiply_int(3, -4), -12)
AssertionError: 12 != -12

   - [#   2] AOD datasets.GPT_4.Zero_shot1.programs.program_069: [0.22102 s] killed by test_4 (datasets.GPT_4.Zero_shot1.tests.test_069.TestVersion)

Traceback (most recent call last):
  File "C:\Users\skaspers\OneDrive - Capgemini\Documents\Prompted Testsuite Analysis\.\datasets\GPT_4\Zero_shot1\tests\test_069.py", line 15, in test_4
    self.assertEqual(multiply_int(3, -4), -12)
  File "datasets.GPT_4.Zero_shot1.programs.program_069", line 3, in multiply_int
  File "datasets.GPT_4.Zero_shot1.programs.program_069", line 3, in multiply_int
  File "datasets.GPT_4.Zero_shot1.programs.program_069", line 3, in multiply_int
  [Previous line repeated 983 more times]
  File "datasets.GPT_4.Zero_shot1.programs.program_069", line 2, in multiply_int
RecursionError: maximum recursion depth exceeded in comparison

   - [#   3] AOR datasets.GPT_4.Zero_shot1.programs.program_069: [0.00000 s] killed by test_4 (datasets.GPT_4.Zero_shot1.tests.test_069.TestVersion)

Traceback (most recent call last):
  File "C:\Users\skaspers\OneDrive - Capgemini\Documents\Prompted Testsuite Analysis\.\datasets\GPT_4\Zero_shot1\tests\test_069.py", line 15, in test_4
    self.assertEqual(multiply_int(3, -4), -12)
AssertionError: 12 != -12

   - [#   4] AOR datasets.GPT_4.Zero_shot1.programs.program_069: [0.22139 s] killed by test_4 (datasets.GPT_4.Zero_shot1.tests.test_069.TestVersion)

Traceback (most recent call last):
  File "C:\Users\skaspers\OneDrive - Capgemini\Documents\Prompted Testsuite Analysis\.\datasets\GPT_4\Zero_shot1\tests\test_069.py", line 15, in test_4
    self.assertEqual(multiply_int(3, -4), -12)
  File "datasets.GPT_4.Zero_shot1.programs.program_069", line 3, in multiply_int
  File "datasets.GPT_4.Zero_shot1.programs.program_069", line 3, in multiply_int
  File "datasets.GPT_4.Zero_shot1.programs.program_069", line 3, in multiply_int
  [Previous line repeated 983 more times]
  File "datasets.GPT_4.Zero_shot1.programs.program_069", line 2, in multiply_int
RecursionError: maximum recursion depth exceeded in comparison

   - [#   5] AOR datasets.GPT_4.Zero_shot1.programs.program_069: [0.00000 s] killed by test_1 (datasets.GPT_4.Zero_shot1.tests.test_069.TestVersion)

Traceback (most recent call last):
  File "C:\Users\skaspers\OneDrive - Capgemini\Documents\Prompted Testsuite Analysis\.\datasets\GPT_4\Zero_shot1\tests\test_069.py", line 6, in test_1
    self.assertEqual(multiply_int(3, 4), 12)
AssertionError: 0 != 12

   - [#   6] AOR datasets.GPT_4.Zero_shot1.programs.program_069: [0.22195 s] killed by test_1 (datasets.GPT_4.Zero_shot1.tests.test_069.TestVersion)

Traceback (most recent call last):
  File "C:\Users\skaspers\OneDrive - Capgemini\Documents\Prompted Testsuite Analysis\.\datasets\GPT_4\Zero_shot1\tests\test_069.py", line 6, in test_1
    self.assertEqual(multiply_int(3, 4), 12)
  File "datasets.GPT_4.Zero_shot1.programs.program_069", line 9, in multiply_int
  File "datasets.GPT_4.Zero_shot1.programs.program_069", line 9, in multiply_int
  File "datasets.GPT_4.Zero_shot1.programs.program_069", line 9, in multiply_int
  [Previous line repeated 983 more times]
  File "datasets.GPT_4.Zero_shot1.programs.program_069", line 2, in multiply_int
RecursionError: maximum recursion depth exceeded in comparison

   - [#   7] COI datasets.GPT_4.Zero_shot1.programs.program_069: [0.22193 s] killed by test_1 (datasets.GPT_4.Zero_shot1.tests.test_069.TestVersion)

Traceback (most recent call last):
  File "C:\Users\skaspers\OneDrive - Capgemini\Documents\Prompted Testsuite Analysis\.\datasets\GPT_4\Zero_shot1\tests\test_069.py", line 6, in test_1
    self.assertEqual(multiply_int(3, 4), 12)
  File "datasets.GPT_4.Zero_shot1.programs.program_069", line 3, in multiply_int
  File "datasets.GPT_4.Zero_shot1.programs.program_069", line 9, in multiply_int
  File "datasets.GPT_4.Zero_shot1.programs.program_069", line 9, in multiply_int
  File "datasets.GPT_4.Zero_shot1.programs.program_069", line 9, in multiply_int
  [Previous line repeated 982 more times]
  File "datasets.GPT_4.Zero_shot1.programs.program_069", line 2, in multiply_int
RecursionError: maximum recursion depth exceeded in comparison

   - [#   8] COI datasets.GPT_4.Zero_shot1.programs.program_069: [0.00000 s] killed by test_1 (datasets.GPT_4.Zero_shot1.tests.test_069.TestVersion)

Traceback (most recent call last):
  File "C:\Users\skaspers\OneDrive - Capgemini\Documents\Prompted Testsuite Analysis\.\datasets\GPT_4\Zero_shot1\tests\test_069.py", line 6, in test_1
    self.assertEqual(multiply_int(3, 4), 12)
AssertionError: 0 != 12

   - [#   9] COI datasets.GPT_4.Zero_shot1.programs.program_069: [0.00000 s] killed by test_1 (datasets.GPT_4.Zero_shot1.tests.test_069.TestVersion)

Traceback (most recent call last):
  File "C:\Users\skaspers\OneDrive - Capgemini\Documents\Prompted Testsuite Analysis\.\datasets\GPT_4\Zero_shot1\tests\test_069.py", line 6, in test_1
    self.assertEqual(multiply_int(3, 4), 12)
AssertionError: 3 != 12

   - [#  10] ROR datasets.GPT_4.Zero_shot1.programs.program_069: [0.20689 s] killed by test_1 (datasets.GPT_4.Zero_shot1.tests.test_069.TestVersion)

Traceback (most recent call last):
  File "C:\Users\skaspers\OneDrive - Capgemini\Documents\Prompted Testsuite Analysis\.\datasets\GPT_4\Zero_shot1\tests\test_069.py", line 6, in test_1
    self.assertEqual(multiply_int(3, 4), 12)
  File "datasets.GPT_4.Zero_shot1.programs.program_069", line 3, in multiply_int
  File "datasets.GPT_4.Zero_shot1.programs.program_069", line 9, in multiply_int
  File "datasets.GPT_4.Zero_shot1.programs.program_069", line 9, in multiply_int
  File "datasets.GPT_4.Zero_shot1.programs.program_069", line 9, in multiply_int
  [Previous line repeated 982 more times]
  File "datasets.GPT_4.Zero_shot1.programs.program_069", line 2, in multiply_int
RecursionError: maximum recursion depth exceeded in comparison

   - [#  11] ROR datasets.GPT_4.Zero_shot1.programs.program_069: [0.22182 s] killed by test_2 (datasets.GPT_4.Zero_shot1.tests.test_069.TestVersion)

Traceback (most recent call last):
  File "C:\Users\skaspers\OneDrive - Capgemini\Documents\Prompted Testsuite Analysis\.\datasets\GPT_4\Zero_shot1\tests\test_069.py", line 9, in test_2
    self.assertEqual(multiply_int(5, 0), 0)
  File "datasets.GPT_4.Zero_shot1.programs.program_069", line 3, in multiply_int
  File "datasets.GPT_4.Zero_shot1.programs.program_069", line 3, in multiply_int
  File "datasets.GPT_4.Zero_shot1.programs.program_069", line 3, in multiply_int
  [Previous line repeated 983 more times]
  File "datasets.GPT_4.Zero_shot1.programs.program_069", line 2, in multiply_int
RecursionError: maximum recursion depth exceeded in comparison

   - [#  12] ROR datasets.GPT_4.Zero_shot1.programs.program_069: [0.00000 s] killed by test_1 (datasets.GPT_4.Zero_shot1.tests.test_069.TestVersion)

Traceback (most recent call last):
  File "C:\Users\skaspers\OneDrive - Capgemini\Documents\Prompted Testsuite Analysis\.\datasets\GPT_4\Zero_shot1\tests\test_069.py", line 6, in test_1
    self.assertEqual(multiply_int(3, 4), 12)
AssertionError: 0 != 12

   - [#  13] ROR datasets.GPT_4.Zero_shot1.programs.program_069: [0.00000 s] killed by test_1 (datasets.GPT_4.Zero_shot1.tests.test_069.TestVersion)

Traceback (most recent call last):
  File "C:\Users\skaspers\OneDrive - Capgemini\Documents\Prompted Testsuite Analysis\.\datasets\GPT_4\Zero_shot1\tests\test_069.py", line 6, in test_1
    self.assertEqual(multiply_int(3, 4), 12)
AssertionError: 3 != 12

[*] Mutation score [1.40915 s]: 100.0%
   - all: 13
   - killed: 13 (100.0%)
   - survived: 0 (0.0%)
   - incompetent: 0 (0.0%)
   - timeout: 0 (0.0%)
HI SANDER, RUNNING MUTPY FROM: C:\Users\skaspers\OneDrive - Capgemini\Documents\Prompted Testsuite Analysis\.venv38\lib\site-packages\mutpy\commandline.py
