[*] Start mutation process:
   - targets: datasets.GPT_4.Zero_shot1.programs.program_091
   - tests: datasets.GPT_4.Zero_shot1.tests.test_091
[*] 7 tests passed:
   - datasets.GPT_4.Zero_shot1.tests.test_091 [0.00000 s]
[*] Start mutants generation and execution:
   - [#   1] AOR datasets.GPT_4.Zero_shot1.programs.program_091: [0.00000 s] killed by test_1 (datasets.GPT_4.Zero_shot1.tests.test_091.TestVersion)

Traceback (most recent call last):
  File "C:\Users\skaspers\OneDrive - Capgemini\Documents\Prompted Testsuite Analysis\.\datasets\GPT_4\Zero_shot1\tests\test_091.py", line 6, in test_1
    self.assertEqual(find_even_pair([1, 3, 5]), 3)
AssertionError: 9 != 3

   - [#   2] AOR datasets.GPT_4.Zero_shot1.programs.program_091: [0.00000 s] killed by test_1 (datasets.GPT_4.Zero_shot1.tests.test_091.TestVersion)

Traceback (most recent call last):
  File "C:\Users\skaspers\OneDrive - Capgemini\Documents\Prompted Testsuite Analysis\.\datasets\GPT_4\Zero_shot1\tests\test_091.py", line 6, in test_1
    self.assertEqual(find_even_pair([1, 3, 5]), 3)
AssertionError: 0 != 3

   - [#   3] ASR datasets.GPT_4.Zero_shot1.programs.program_091: [0.00000 s] killed by test_1 (datasets.GPT_4.Zero_shot1.tests.test_091.TestVersion)

Traceback (most recent call last):
  File "C:\Users\skaspers\OneDrive - Capgemini\Documents\Prompted Testsuite Analysis\.\datasets\GPT_4\Zero_shot1\tests\test_091.py", line 6, in test_1
    self.assertEqual(find_even_pair([1, 3, 5]), 3)
AssertionError: -3 != 3

   - [#   4] COI datasets.GPT_4.Zero_shot1.programs.program_091: [0.00000 s] killed by test_1 (datasets.GPT_4.Zero_shot1.tests.test_091.TestVersion)

Traceback (most recent call last):
  File "C:\Users\skaspers\OneDrive - Capgemini\Documents\Prompted Testsuite Analysis\.\datasets\GPT_4\Zero_shot1\tests\test_091.py", line 6, in test_1
    self.assertEqual(find_even_pair([1, 3, 5]), 3)
AssertionError: 0 != 3

   - [#   5] LOR datasets.GPT_4.Zero_shot1.programs.program_091: [0.00000 s] killed by test_1 (datasets.GPT_4.Zero_shot1.tests.test_091.TestVersion)

Traceback (most recent call last):
  File "C:\Users\skaspers\OneDrive - Capgemini\Documents\Prompted Testsuite Analysis\.\datasets\GPT_4\Zero_shot1\tests\test_091.py", line 6, in test_1
    self.assertEqual(find_even_pair([1, 3, 5]), 3)
AssertionError: 0 != 3

   - [#   6] ROR datasets.GPT_4.Zero_shot1.programs.program_091: [0.00000 s] killed by test_1 (datasets.GPT_4.Zero_shot1.tests.test_091.TestVersion)

Traceback (most recent call last):
  File "C:\Users\skaspers\OneDrive - Capgemini\Documents\Prompted Testsuite Analysis\.\datasets\GPT_4\Zero_shot1\tests\test_091.py", line 6, in test_1
    self.assertEqual(find_even_pair([1, 3, 5]), 3)
AssertionError: 0 != 3

[*] Mutation score [0.06290 s]: 100.0%
   - all: 6
   - killed: 6 (100.0%)
   - survived: 0 (0.0%)
   - incompetent: 0 (0.0%)
   - timeout: 0 (0.0%)
HI SANDER, RUNNING MUTPY FROM: C:\Users\skaspers\OneDrive - Capgemini\Documents\Prompted Testsuite Analysis\.venv38\lib\site-packages\mutpy\commandline.py
