[*] Start mutation process:
   - targets: datasets.GPT_4.Few_shot1.programs.program_072
   - tests: datasets.GPT_4.Few_shot1.tests.test_072
[*] 9 tests passed:
   - datasets.GPT_4.Few_shot1.tests.test_072 [0.00101 s]
[*] Start mutants generation and execution:
   - [#   1] ASR datasets.GPT_4.Few_shot1.programs.program_072: [0.00199 s] killed by test_max_occurrences_basic (datasets.GPT_4.Few_shot1.tests.test_072.TestVersion)

Traceback (most recent call last):
  File "C:\Users\skaspers\OneDrive - Capgemini\Documents\Prompted Testsuite Analysis\.\datasets\GPT_4\Few_shot1\tests\test_072.py", line 5, in test_max_occurrences_basic
    def test_max_occurrences_basic(self): self.assertEqual(max_occurrences([1, 2, 2, 3]), 2)
AssertionError: 1 != 2

[*] Mutation score [0.03454 s]: 100.0%
   - all: 1
   - killed: 1 (100.0%)
   - survived: 0 (0.0%)
   - incompetent: 0 (0.0%)
   - timeout: 0 (0.0%)
HI SANDER, RUNNING MUTPY FROM: C:\Users\skaspers\OneDrive - Capgemini\Documents\Prompted Testsuite Analysis\.venv38\lib\site-packages\mutpy\commandline.py
