coverage:
  all_nodes: 0
  covered_nodes: 0
mutation_score: 100.0
mutations:
- exception_traceback: "Traceback (most recent call last):\n  File \"C:\\Users\\skaspers\\\
    OneDrive - Capgemini\\Documents\\Prompted Testsuite Analysis\\.\\datasets\\GPT_4\\\
    Chain_of_thought1\\tests\\test_092.py\", line 15, in test_sixty_four\n    def\
    \ test_sixty_four(self): self.assertEqual(next_power_of_2(64), 64)\nAssertionError:\
    \ 128 != 64\n"
  killer: test_sixty_four (datasets.GPT_4.Chain_of_thought1.tests.test_092.TestVersion)
  module: &id001 !!python/module:datasets.GPT_4.Chain_of_thought1.programs.program_092 ''
  mutations:
  - lineno: 2
    operator: AOR
  number: 1
  status: killed
  tests_run: 7
  time: 0.0011036396026611328
- exception_traceback: "Traceback (most recent call last):\n  File \"C:\\Users\\skaspers\\\
    OneDrive - Capgemini\\Documents\\Prompted Testsuite Analysis\\.\\datasets\\GPT_4\\\
    Chain_of_thought1\\tests\\test_092.py\", line 9, in test_five\n    def test_five(self):\
    \ self.assertEqual(next_power_of_2(5), 8)\n  File \"datasets.GPT_4.Chain_of_thought1.programs.program_092\"\
    , line 10, in next_power_of_2\nValueError: negative shift count\n"
  killer: test_five (datasets.GPT_4.Chain_of_thought1.tests.test_092.TestVersion)
  module: *id001
  mutations:
  - lineno: 8
    operator: ASR
  number: 2
  status: killed
  tests_run: 2
  time: 0.002003908157348633
- exception_traceback: "Traceback (most recent call last):\n  File \"C:\\Users\\skaspers\\\
    OneDrive - Capgemini\\Documents\\Prompted Testsuite Analysis\\.\\datasets\\GPT_4\\\
    Chain_of_thought1\\tests\\test_092.py\", line 27, in test_boolean_input\n    def\
    \ test_boolean_input(self): self.assertEqual(next_power_of_2(True), 1)\nAssertionError:\
    \ 2 != 1\n"
  killer: test_boolean_input (datasets.GPT_4.Chain_of_thought1.tests.test_092.TestVersion)
  module: *id001
  mutations:
  - lineno: 2
    operator: COD
  number: 3
  status: killed
  tests_run: 1
  time: 0.001001119613647461
- exception_traceback: "Traceback (most recent call last):\n  File \"C:\\Users\\skaspers\\\
    OneDrive - Capgemini\\Documents\\Prompted Testsuite Analysis\\.\\datasets\\GPT_4\\\
    Chain_of_thought1\\tests\\test_092.py\", line 27, in test_boolean_input\n    def\
    \ test_boolean_input(self): self.assertEqual(next_power_of_2(True), 1)\nAssertionError:\
    \ 2 != 1\n"
  killer: test_boolean_input (datasets.GPT_4.Chain_of_thought1.tests.test_092.TestVersion)
  module: *id001
  mutations:
  - lineno: 2
    operator: COI
  number: 4
  status: killed
  tests_run: 1
  time: 0.0
- exception_traceback: "Traceback (most recent call last):\n  File \"C:\\Users\\skaspers\\\
    OneDrive - Capgemini\\Documents\\Prompted Testsuite Analysis\\.\\datasets\\GPT_4\\\
    Chain_of_thought1\\tests\\test_092.py\", line 9, in test_five\n    def test_five(self):\
    \ self.assertEqual(next_power_of_2(5), 8)\nAssertionError: 1 != 8\n"
  killer: test_five (datasets.GPT_4.Chain_of_thought1.tests.test_092.TestVersion)
  module: *id001
  mutations:
  - lineno: 6
    operator: COI
  number: 5
  status: killed
  tests_run: 2
  time: 0.0
- exception_traceback: "Traceback (most recent call last):\n  File \"C:\\Users\\skaspers\\\
    OneDrive - Capgemini\\Documents\\Prompted Testsuite Analysis\\.\\datasets\\GPT_4\\\
    Chain_of_thought1\\tests\\test_092.py\", line 9, in test_five\n    def test_five(self):\
    \ self.assertEqual(next_power_of_2(5), 8)\nAssertionError: 5 != 8\n"
  killer: test_five (datasets.GPT_4.Chain_of_thought1.tests.test_092.TestVersion)
  module: *id001
  mutations:
  - lineno: 2
    operator: LCR
  number: 6
  status: killed
  tests_run: 2
  time: 0.0
- exception_traceback: "Traceback (most recent call last):\n  File \"C:\\Users\\skaspers\\\
    OneDrive - Capgemini\\Documents\\Prompted Testsuite Analysis\\.\\datasets\\GPT_4\\\
    Chain_of_thought1\\tests\\test_092.py\", line 27, in test_boolean_input\n    def\
    \ test_boolean_input(self): self.assertEqual(next_power_of_2(True), 1)\nAssertionError:\
    \ 2 != 1\n"
  killer: test_boolean_input (datasets.GPT_4.Chain_of_thought1.tests.test_092.TestVersion)
  module: *id001
  mutations:
  - lineno: 2
    operator: LOR
  number: 7
  status: killed
  tests_run: 1
  time: 0.0010030269622802734
- exception_traceback: null
  killer: null
  module: *id001
  mutations:
  - lineno: 7
    operator: LOR
  number: 8
  status: timeout
  tests_run: null
  time: 5.039357662200928
- exception_traceback: "Traceback (most recent call last):\n  File \"C:\\Users\\skaspers\\\
    OneDrive - Capgemini\\Documents\\Prompted Testsuite Analysis\\.\\datasets\\GPT_4\\\
    Chain_of_thought1\\tests\\test_092.py\", line 9, in test_five\n    def test_five(self):\
    \ self.assertEqual(next_power_of_2(5), 8)\nAssertionError: 0 != 8\n"
  killer: test_five (datasets.GPT_4.Chain_of_thought1.tests.test_092.TestVersion)
  module: *id001
  mutations:
  - lineno: 10
    operator: LOR
  number: 9
  status: killed
  tests_run: 2
  time: 0.0009527206420898438
- exception_traceback: "Traceback (most recent call last):\n  File \"C:\\Users\\skaspers\\\
    OneDrive - Capgemini\\Documents\\Prompted Testsuite Analysis\\.\\datasets\\GPT_4\\\
    Chain_of_thought1\\tests\\test_092.py\", line 9, in test_five\n    def test_five(self):\
    \ self.assertEqual(next_power_of_2(5), 8)\nAssertionError: 1 != 8\n"
  killer: test_five (datasets.GPT_4.Chain_of_thought1.tests.test_092.TestVersion)
  module: *id001
  mutations:
  - lineno: 6
    operator: ROR
  number: 10
  status: killed
  tests_run: 2
  time: 0.0009562969207763672
number_of_tests: 10
targets:
- datasets.GPT_4.Chain_of_thought1.programs.program_092
tests:
- name: datasets.GPT_4.Chain_of_thought1.tests.test_092
  target: null
  time: 0.0
time_stats:
  create_mutant_module: 0.0010457038879394531
  create_target_ast: 0.0010151863098144531
  mutate_module: 5.1006317138671875
  run_tests_with_mutant: 5.0483503341674805
total_time: 5.106682300567627
